Workbook

Sheet Погрешности косвенные (Шаблон)
A1: Название переменной
A2: Формулы частных производных по переменным: | B2: 1 | C2: 1 | D2: 1 | E2: 1
A3: Среднее значение переменной | B3: 1 | C3: 1 | D3: 1 | E3: 1
A4: Среднее значение функции
A5: Абсолютные погрешности переменных
A6: Относительные погрешности переменных
A7: Слагаемые | B7: =B5*B5*B2*B2 -> 0
A8: Абсолютная погрешность функции | B8: =SQRT(SUM(7:7)) -> 0
A9: Относительные погрешности функции | B9: =B8/B3 -> 0

Sheet МНК (Шаблон)
A1: x | B1: y | C1: Квадрат разности (x-xср)2 | D1: Квадрат разности (y-yср)2 | E1: Разность x-xср | F1: Разность y-yср | G1: Произведение (x-xср)(y-yср) | H1: d | I1: d2 | J1: Δy | L1: Среднее xср | M1: Среднее yср | N1: b | O1: a | P1: D | Q1: Sb2 | R1: Sa2
A2: 0.081666667 | B2: 48.691667 | C2: =(A2-$L$2)*(A2-$L$2) -> 0.67521437 | D2: =(B2-$M$2)*(B2-$M$2) -> 63998.399 | E2: =A2-$L$2 -> -0.82171429 | F2: =B2-$M$2 -> -252.97905 | G2: =E2*F2 -> 207.8765 | H2: =B2-($O$2+$N$2*A2) -> 0.42403697 | I2: =H2*H2 -> 0.17980735 | J2: =SQRT(4*$R$2+4*$Q$2*A2*A2) -> 4.9576164 | L2: =SUM(A:A)/COUNT(A:A) -> 0.90338095 | M2: =SUM(B:B)/COUNT(B:B) -> 301.67071 | N2: =SUM(G:G)/SUM(C:C) -> 308.38345 | O2: =M2-N2*L2 -> 23.082981 | P2: =SUM(C:C) -> 1.902757 | Q2: =1/P2*SUM(I:I)/(COUNT(I:I)-2) -> 5.6135134 | R2: =(1/COUNT(I:I)+L2*L2/P2)*SUM(I:I)/(COUNT(I:I)-2) -> 6.1070511
A3: 0.384 | B3: 141.54 | C3: =(A3-$L$2)*(A3-$L$2) -> 0.26975657 | D3: =(B3-$M$2)*(B3-$M$2) -> 25641.846 | E3: =A3-$L$2 -> -0.51938095 | F3: =B3-$M$2 -> -160.13071 | G3: =E3*F3 -> 83.168843 | H3: =B3-($O$2+$N$2*A3) -> 0.037774563 | I3: =H3*H3 -> 0.0014269176 | J3: =SQRT(4*$R$2+4*$Q$2*A3*A3) -> 5.2668007 | Q3: Sb | R3: Sa
A4: 0.665 | B4: 228.875 | C4: =(A4-$L$2)*(A4-$L$2) -> 0.056825478 | D4: =(B4-$M$2)*(B4-$M$2) -> 5299.216 | E4: =A4-$L$2 -> -0.23838095 | F4: =B4-$M$2 -> -72.795714 | G4: =E4*F4 -> 17.353112 | H4: =B4-($O$2+$N$2*A4) -> 0.71702571 | I4: =H4*H4 -> 0.51412587 | J4: =SQRT(4*$R$2+4*$Q$2*A4*A4) -> 5.8615653 | Q4: =SQRT(Q2) -> 2.3692854 | R4: =SQRT(R2) -> 2.4712448
A5: 0.94166667 | B5: 310.74167 | C5: =(A5-$L$2)*(A5-$L$2) -> 0.0014657959 | D5: =(B5-$M$2)*(B5-$M$2) -> 82.282177 | E5: =A5-$L$2 -> 0.038285714 | F5: =B5-$M$2 -> 9.0709524 | G5: =E5*F5 -> 0.34728789 | H5: =B5-($O$2+$N$2*A5) -> -2.7357282 | I5: =H5*H5 -> 7.4842088 | J5: =SQRT(4*$R$2+4*$Q$2*A5*A5) -> 6.6587555 | Q5: 2Sb = Δb | R5: 2Sa = Δa
A6: 1.176 | B6: 388.98 | C6: =(A6-$L$2)*(A6-$L$2) -> 0.074321145 | D6: =(B6-$M$2)*(B6-$M$2) -> 7622.9114 | E6: =A6-$L$2 -> 0.27261905 | F6: =B6-$M$2 -> 87.309286 | G6: =E6*F6 -> 23.802174 | H6: =B6-($O$2+$N$2*A6) -> 3.2380839 | I6: =H6*H6 -> 10.485187 | J6: =SQRT(4*$R$2+4*$Q$2*A6*A6) -> 7.4485986 | Q6: =Q4*2 -> 4.7385708 | R6: =R4*2 -> 4.9424897
A7: 1.4363333 | B7: 461.10167 | C7: =(A7-$L$2)*(A7-$L$2) -> 0.28403824 | D7: =(B7-$M$2)*(B7-$M$2) -> 25418.229 | E7: =A7-$L$2 -> 0.53295238 | F7: =B7-$M$2 -> 159.43095 | G7: =E7*F7 -> 84.969106 | H7: =B7-($O$2+$N$2*A7) -> -4.9227404 | I7: =H7*H7 -> 24.233373 | J7: =SQRT(4*$R$2+4*$Q$2*A7*A7) -> 8.4114278
A8: 1.639 | B8: 531.765 | C8: =(A8-$L$2)*(A8-$L$2) -> 0.54113538 | D8: =(B8-$M$2)*(B8-$M$2) -> 52943.38 | E8: =A8-$L$2 -> 0.73561905 | F8: =B8-$M$2 -> 230.09429 | G8: =E8*F8 -> 169.26174 | H8: =B8-($O$2+$N$2*A8) -> 3.2415475 | I8: =H8*H8 -> 10.50763 | J8: =SQRT(4*$R$2+4*$Q$2*A8*A8) -> 9.2058134

Sheet предисловие
A1: Берете замеры, вставляете в таблицу 1 среднее время и прочие вещи, которые надо считать, появятся сами
A3: Все погрешности и графики основаны на первой таблице и параметрах установки
A5: На листы печать внимание оформлять не нужно, это сделано для проверки наличия всех графиков и таблиц после подсчета
A7: Далее таблицы вырезаем ножницами и вставляем в отчет (можно и копировать, но ножницы как по мне лучше)
A9: Радуемся сделанной лабе!

Sheet Таблица 1
A1: Масса груза, г | B1: Положение утяжелителей
B2: 1.риска | C2: 2.риска | D2: 3.риска | E2: 4.риска | F2: 5.риска | G2: 6.риска
A3: =0.047+0.22 -> 0.267 | B3: 4.62 | C3: 5.36 | D3: 6.27 | E3: 7.23 | F3: 8.22 | G3: 8.82
B4: 5.01 | C4: 5.98 | D4: 6.08 | E4: 7.08 | F4: 8.43 | G4: 9.09
B5: 4.83 | C5: 5.38 | D5: 6.27 | E5: 7.63 | F5: 8.56 | G5: 9.16
B6: 4.59 | C6: 5.45 | D6: 6.13 | E6: 7.45 | F6: 8.34 | G6: 8.99
A7: =0.047+0.22*2 -> 0.487 | B7: 3.56 | C7: 4.02 | D7: 4.62 | E7: 5.76 | F7: 5.97 | G7: 7.26
B8: 3.53 | C8: 3.89 | D8: 4.54 | E8: 5.19 | F8: 6.47 | G8: 6.45
B9: 3.66 | C9: 4.11 | D9: 4.77 | E9: 5.38 | F9: 6.24 | G9: 6.89
B10: 3.5 | C10: 3.97 | D10: 4.56 | E10: 5.47 | F10: 6.13 | G10: 6.65
A11: =0.047+0.22*3 -> 0.707 | B11: 3.04 | C11: 3.47 | D11: 3.83 | E11: 4.33 | F11: 4.9 | G11: 5.73
B12: 3.05 | C12: 3.43 | D12: 4.11 | E12: 4.55 | F12: 4.64 | G12: 5.48
B13: 2.92 | C13: 3.48 | D13: 4.28 | E13: 4.47 | F13: 4.77 | G13: 5.46
B14: 2.96 | C14: 3.56 | D14: 4.01 | E14: 4.36 | F14: 4.69 | G14: 5.68
A15: =0.047+0.22*4 -> 0.927 | B15: 2.64 | C15: 3.05 | D15: 3.44 | E15: 4.1 | F15: 4.43 | G15: 5
B16: 2.6 | C16: 2.92 | D16: 3.35 | E16: 3.76 | F16: 4.66 | G16: 5.22
B17: 2.67 | C17: 3.2 | D17: 3.3 | E17: 3.75 | F17: 4.53 | G17: 5.13
B18: 2.71 | C18: 3.08 | D18: 3.41 | E18: 3.84 | F18: 4.68 | G18: 5.09

Sheet Таблица 2
A2: Масса груза, г | B2: tср, с | C2: a, м/с2 | D2: ε, с-2 | E2: M, Н*м
A3: ='Таблица 1'!A3 -> 0.267 | B3: ='Таблица 1'!B6 -> 4.59 | C3: ='Параметры установки'!$A$2*2/B3/B3 -> 0.066451175 | D3: =2*C3/'Параметры установки'!$B$2 -> 2.8891815 | E3: =$A$3*'Параметры установки'!$B$2/2*(9.8-C3) -> 0.059773723
B4: ='Таблица 1'!C6 -> 5.45 | C4: ='Параметры установки'!$A$2*2/B4/B4 -> 0.04713408 | D4: =2*C4/'Параметры установки'!$B$2 -> 2.0493078 | E4: =$A$3*'Параметры установки'!$B$2/2*(9.8-C4) -> 0.05989235
B5: ='Таблица 1'!D6 -> 6.13 | C5: ='Параметры установки'!$A$2*2/B5/B5 -> 0.037256932 | D5: =2*C5/'Параметры установки'!$B$2 -> 1.6198666 | E5: =$A$3*'Параметры установки'!$B$2/2*(9.8-C5) -> 0.059953005
B6: ='Таблица 1'!E6 -> 7.45 | C6: ='Параметры установки'!$A$2*2/B6/B6 -> 0.025224089 | D6: =2*C6/'Параметры установки'!$B$2 -> 1.0966995 | E6: =$A$3*'Параметры установки'!$B$2/2*(9.8-C6) -> 0.060026899
B7: ='Таблица 1'!F6 -> 8.34 | C7: ='Параметры установки'!$A$2*2/B7/B7 -> 0.020127783 | D7: =2*C7/'Параметры установки'!$B$2 -> 0.87512099 | E7: =$A$3*'Параметры установки'!$B$2/2*(9.8-C7) -> 0.060058195
B8: ='Таблица 1'!G6 -> 8.99 | C8: ='Параметры установки'!$A$2*2/B8/B8 -> 0.017322424 | D8: =2*C8/'Параметры установки'!$B$2 -> 0.75314885 | E8: =$A$3*'Параметры установки'!$B$2/2*(9.8-C8) -> 0.060075423
A9: ='Таблица 1'!A7 -> 0.487 | B9: ='Таблица 1'!B10 -> 3.5 | C9: ='Параметры установки'!$A$2*2/B9/B9 -> 0.11428571 | D9: =2*C9/'Параметры установки'!$B$2 -> 4.9689441 | E9: =$A$9*'Параметры установки'!$B$2/2*(9.8-C9) -> 0.10848969
B10: ='Таблица 1'!C10 -> 3.97 | C10: ='Параметры установки'!$A$2*2/B10/B10 -> 0.088827415 | D10: =2*C10/'Параметры установки'!$B$2 -> 3.8620615 | E10: =$A$9*'Параметры установки'!$B$2/2*(9.8-C10) -> 0.10877484
B11: ='Таблица 1'!D10 -> 4.56 | C11: ='Параметры установки'!$A$2*2/B11/B11 -> 0.067328409 | D11: =2*C11/'Параметры установки'!$B$2 -> 2.9273221 | E11: =$A$9*'Параметры установки'!$B$2/2*(9.8-C11) -> 0.10901565
B12: ='Таблица 1'!E10 -> 5.47 | C12: ='Параметры установки'!$A$2*2/B12/B12 -> 0.046790036 | D12: =2*C12/'Параметры установки'!$B$2 -> 2.0343494 | E12: =$A$9*'Параметры установки'!$B$2/2*(9.8-C12) -> 0.1092457
B13: ='Таблица 1'!F10 -> 6.13 | C13: ='Параметры установки'!$A$2*2/B13/B13 -> 0.037256932 | D13: =2*C13/'Параметры установки'!$B$2 -> 1.6198666 | E13: =$A$9*'Параметры установки'!$B$2/2*(9.8-C13) -> 0.10935249
B14: ='Таблица 1'!G10 -> 6.65 | C14: ='Параметры установки'!$A$2*2/B14/B14 -> 0.031658093 | D14: =2*C14/'Параметры установки'!$B$2 -> 1.3764388 | E14: =$A$9*'Параметры установки'!$B$2/2*(9.8-C14) -> 0.1094152
A15: ='Таблица 1'!A11 -> 0.707 | B15: ='Таблица 1'!B14 -> 2.96 | C15: ='Параметры установки'!$A$2*2/B15/B15 -> 0.15978817 | D15: =2*C15/'Параметры установки'!$B$2 -> 6.9473116 | E15: =$A$15*'Параметры установки'!$B$2/2*(9.8-C15) -> 0.15675948
B16: ='Таблица 1'!C14 -> 3.56 | C16: ='Параметры установки'!$A$2*2/B16/B16 -> 0.11046585 | D16: =2*C16/'Параметры установки'!$B$2 -> 4.8028631 | E16: =$A$15*'Параметры установки'!$B$2/2*(9.8-C16) -> 0.15756151
B17: ='Таблица 1'!D14 -> 4.01 | C17: ='Параметры установки'!$A$2*2/B17/B17 -> 0.087064135 | D17: =2*C17/'Параметры установки'!$B$2 -> 3.7853972 | E17: =$A$15*'Параметры установки'!$B$2/2*(9.8-C17) -> 0.15794205
B18: ='Таблица 1'!E14 -> 4.36 | C18: ='Параметры установки'!$A$2*2/B18/B18 -> 0.073646999 | D18: =2*C18/'Параметры установки'!$B$2 -> 3.2020435 | E18: =$A$15*'Параметры установки'!$B$2/2*(9.8-C18) -> 0.15816023
B19: ='Таблица 1'!F14 -> 4.69 | C19: ='Параметры установки'!$A$2*2/B19/B19 -> 0.063647647 | D19: =2*C19/'Параметры установки'!$B$2 -> 2.767289 | E19: =$A$15*'Параметры установки'!$B$2/2*(9.8-C19) -> 0.15832283
B20: ='Таблица 1'!G14 -> 5.68 | C20: ='Параметры установки'!$A$2*2/B20/B20 -> 0.043394168 | D20: =2*C20/'Параметры установки'!$B$2 -> 1.8867029 | E20: =$A$15*'Параметры установки'!$B$2/2*(9.8-C20) -> 0.15865217
A21: ='Таблица 1'!A15 -> 0.927 | B21: ='Таблица 1'!B18 -> 2.71 | C21: ='Параметры установки'!$A$2*2/B21/B21 -> 0.19062921 | D21: =2*C21/'Параметры установки'!$B$2 -> 8.2882266 | E21: =$A$21*'Параметры установки'!$B$2/2*(9.8-C21) -> 0.20488139
B22: ='Таблица 1'!C18 -> 3.08 | C22: ='Параметры установки'!$A$2*2/B22/B22 -> 0.14757969 | D22: =2*C22/'Параметры установки'!$B$2 -> 6.4165084 | E22: =$A$21*'Параметры установки'!$B$2/2*(9.8-C22) -> 0.20579925
B23: ='Таблица 1'!D18 -> 3.41 | C23: ='Параметры установки'!$A$2*2/B23/B23 -> 0.120398 | D23: =2*C23/'Параметры установки'!$B$2 -> 5.2346957 | E23: =$A$21*'Параметры установки'!$B$2/2*(9.8-C23) -> 0.20637879
B24: ='Таблица 1'!E18 -> 3.84 | C24: ='Параметры установки'!$A$2*2/B24/B24 -> 0.094943576 | D24: =2*C24/'Параметры установки'!$B$2 -> 4.1279816 | E24: =$A$21*'Параметры установки'!$B$2/2*(9.8-C24) -> 0.20692151
B25: ='Таблица 1'!F18 -> 4.68 | C25: ='Параметры установки'!$A$2*2/B25/B25 -> 0.063919936 | D25: =2*C25/'Параметры установки'!$B$2 -> 2.7791276 | E25: =$A$21*'Параметры установки'!$B$2/2*(9.8-C25) -> 0.20758296
B26: ='Таблица 1'!G18 -> 5.09 | C26: ='Параметры установки'!$A$2*2/B26/B26 -> 0.054037154 | D26: =2*C26/'Параметры установки'!$B$2 -> 2.3494415 | E26: =$A$21*'Параметры установки'!$B$2/2*(9.8-C26) -> 0.20779367

Sheet Таблица 3
A1: Номера рисок | B1: 1 | C1: 2 | D1: 3 | E1: 4 | F1: 5 | G1: 6
A2: R | B2: ='Параметры установки'!$C$2+(B1-1)*'Параметры установки'!$D$2+'Параметры установки'!$E$2/2 -> 0.077 | C2: ='Параметры установки'!$C$2+(C1-1)*'Параметры установки'!$D$2+'Параметры установки'!$E$2/2 -> 0.102 | D2: ='Параметры установки'!$C$2+(D1-1)*'Параметры установки'!$D$2+'Параметры установки'!$E$2/2 -> 0.127 | E2: ='Параметры установки'!$C$2+(E1-1)*'Параметры установки'!$D$2+'Параметры установки'!$E$2/2 -> 0.152 | F2: ='Параметры установки'!$C$2+(F1-1)*'Параметры установки'!$D$2+'Параметры установки'!$E$2/2 -> 0.177 | G2: ='Параметры установки'!$C$2+(G1-1)*'Параметры установки'!$D$2+'Параметры установки'!$E$2/2 -> 0.202
A3: R2 | B3: =B2*B2 -> 0.005929 | C3: =C2*C2 -> 0.010404 | D3: =D2*D2 -> 0.016129 | E3: =E2*E2 -> 0.023104 | F3: =F2*F2 -> 0.031329 | G3: =G2*G2 -> 0.040804
A4: I | B4: ='МНК рис.1'!N2 -> 0.026372168 | C4: ='МНК рис.2'!N2 -> 0.034197067 | D4: ='МНК рис.3'!N2 -> 0.04135439 | E4: ='МНК рис.4'!N2 -> 0.047610597 | F4: ='МНК рис.5'!N2 -> 0.064695723 | G4: ='МНК рис.6'!N2 -> 0.092486208

Sheet График 1

Sheet График 2

Sheet Печать 1
A1: Таблица 1. Протокол измерений времени падения груза при разной массе груза и разном положении утяжелителей на крестовине
A2: Масса груза, кг | B2: Положение утяжелителей
B3: 1.риска | C3: 2.риска | D3: 3.риска | E3: 4.риска | F3: 5.риска | G3: 6.риска
A4: =0.047+0.22 -> 0.267 | B4: 4.2 | C4: 4.97 | D4: 6 | E4: 6.86 | F4: 7.78 | G4: 8.88
B5: 4.3 | C5: 4.87 | D5: 5.93 | E5: 6.87 | F5: 7.8 | G5: 8.94
B6: 4.36 | C6: 4.95 | D6: 6.04 | E6: 6.96 | F6: 7.91 | G6: 9.02
B7: =SUM(B4:B6)/3 -> 4.2866667 | C7: =SUM(C4:C6)/3 -> 4.93 | D7: =SUM(D4:D6)/3 -> 5.99 | E7: =SUM(E4:E6)/3 -> 6.8966667 | F7: =SUM(F4:F6)/3 -> 7.83 | G7: =SUM(G4:G6)/3 -> 8.9466667
A8: =0.047+0.22*2 -> 0.487 | B8: 3.27 | C8: 3.52 | D8: 4.36 | E8: 4.99 | F8: 5.67 | G8: 6.36
B9: 3.18 | C9: 3.63 | D9: 4.35 | E9: 5.02 | F9: 5.74 | G9: 6.39
B10: 3.13 | C10: 3.64 | D10: 4.17 | E10: 4.96 | F10: 5.65 | G10: 6.37
B11: =SUM(B8:B10)/3 -> 3.1933333 | C11: =SUM(C8:C10)/3 -> 3.5966667 | D11: =SUM(D8:D10)/3 -> 4.2933333 | E11: =SUM(E8:E10)/3 -> 4.99 | F11: =SUM(F8:F10)/3 -> 5.6866667 | G11: =SUM(G8:G10)/3 -> 6.3733333
A12: =0.047+0.22*3 -> 0.707 | B12: 2.51 | C12: 2.94 | D12: 3.45 | E12: 4.14 | F12: 4.64 | G12: 5.24
B13: 2.56 | C13: 2.93 | D13: 3.55 | E13: 4.08 | F13: 4.75 | G13: 5.27
B14: 2.53 | C14: 3.02 | D14: 3.49 | E14: 4.07 | F14: 4.62 | G14: 5.28
B15: =SUM(B12:B14)/3 -> 2.5333333 | C15: =SUM(C12:C14)/3 -> 2.9633333 | D15: =SUM(D12:D14)/3 -> 3.4966667 | E15: =SUM(E12:E14)/3 -> 4.0966667 | F15: =SUM(F12:F14)/3 -> 4.67 | G15: =SUM(G12:G14)/3 -> 5.2633333
A16: =0.047+0.22*4 -> 0.927 | B16: 2.23 | C16: 2.59 | D16: 3.1 | E16: 3.55 | F16: 4.06 | G16: 4.61
B17: 2.23 | C17: 2.59 | D17: 3.06 | E17: 3.56 | F17: 4.01 | G17: 4.56
B18: 2.12 | C18: 2.46 | D18: 3.09 | E18: 3.58 | F18: 4.07 | G18: 4.68
B19: =SUM(B16:B18)/3 -> 2.1933333 | C19: =SUM(C16:C18)/3 -> 2.5466667 | D19: =SUM(D16:D18)/3 -> 3.0833333 | E19: =SUM(E16:E18)/3 -> 3.5633333 | F19: =SUM(F16:F18)/3 -> 4.0466667 | G19: =SUM(G16:G18)/3 -> 4.6166667
A20: Таблица 2. Значения ускорения каретки, углового ускорения крестовины и момента силы натяжения нити для средних значений времени
A21: Масса груза, кг | B21: tср, с | C21: a, м/с2 | D21: ε, с-2 | E21: M, Н*м
A22: 0.267 | B22: 4.2866667 | C22: 0.076188357 | D22: 3.3125373 | E22: 0.059713927
B23: 4.93 | C23: 0.057601554 | D23: 2.5044154 | E23: 0.059828069
B24: 5.99 | C24: 0.039018843 | D24: 1.6964714 | E24: 0.059942185
B25: 6.8966667 | C25: 0.029434019 | D25: 1.27974 | E25: 0.060001046
B26: 7.83 | C26: 0.022835184 | D26: 0.99283408 | E26: 0.060041569
B27: 8.9466667 | C27: 0.017490633 | D27: 0.7604623 | E27: 0.06007439
A28: 0.487 | B28: 3.1933333 | C28: 0.1372902 | D28: 5.969139 | E28: 0.10823201
B29: 3.5966667 | C29: 0.10822502 | D29: 4.7054354 | E29: 0.10855757
B30: 4.2933333 | C30: 0.075951931 | D30: 3.3022579 | E30: 0.10891906
B31: 4.99 | C31: 0.056224674 | D31: 2.444551 | E31: 0.10914003
B32: 5.6866667 | C32: 0.043292483 | D32: 1.8822819 | E32: 0.10928488
B33: 6.3733333 | C33: 0.034466308 | D33: 1.4985351 | E33: 0.10938374
A34: 0.707 | B34: 2.5333333 | C34: 0.21814404 | D34: 9.4845237 | E34: 0.15581056
B35: 2.9633333 | C35: 0.15942889 | D35: 6.9316909 | E35: 0.15676533
B36: 3.4966667 | C36: 0.11450371 | D36: 4.9784223 | E36: 0.15749586
B37: 4.0966667 | C37: 0.083419346 | D37: 3.6269281 | E37: 0.15800132
B38: 4.67 | C38: 0.064193976 | D38: 2.7910424 | E38: 0.15831394
B39: 5.2633333 | C39: 0.050536631 | D39: 2.1972448 | E39: 0.15853602
A40: 0.927 | B40: 2.1933333 | C40: 0.29101727 | D40: 12.652925 | E40: 0.20274102
...

Sheet Печать 2

Sheet Печать 3

Sheet Параметры установки
A1: h | B1: d | C1: l1 | D1: l0 | E1: b
A2: 0.7 | B2: 0.046 | C2: 0.057 | D2: 0.025 | E2: 0.04

Sheet Погрешности прямые (t)
A1: Значения x | B1: Квадрат разности (x-xср)2 | H1: Среднее xср | I1: СКО Sxср | J1: Коэфф. Стьюдента tα,n | K1: Доверительный интервал Δxср | L1: Инструментальная погрешность Δиx | M1: Абсолютная погрешность Δx | N1: Относительная погрешность εx
A2: ='Таблица 1'!B3 -> 4.62 | B2: =(A2-$H$2)*(A2-$H$2) -> 0.04 | H2: =SUM(A:A)/COUNT(A:A) -> 4.82 | I2: =SQRT(SUM(B:B)/COUNT(A:A)/(COUNT(A:A)-1)) -> 0.11269428 | J2: 0.95 | K2: =J2*I2 -> 0.10705956 | L2: 1 | M2: =SQRT(K2*K2+(2/3*L2)*(2/3*L2)) -> 0.67520826 | N2: =M2/H2 -> 0.1400847
A3: ='Таблица 1'!B4 -> 5.01 | B3: =(A3-$H$2)*(A3-$H$2) -> 0.0361
A4: ='Таблица 1'!B5 -> 4.83 | B4: =(A4-$H$2)*(A4-$H$2) -> 0.0001

Sheet Погрешности прямые (a)
A1: Значения x | B1: Квадрат разности (x-xср)2 | H1: Среднее xср | I1: СКО Sxср | J1: Коэфф. Стьюдента tα,n | K1: Доверительный интервал Δxср | L1: Инструментальная погрешность Δиx | M1: Абсолютная погрешность Δx | N1: Относительная погрешность εx
A2: ='Таблица 2'!C3 -> 0.066451175 | B2: =(A2-$H$2)*(A2-$H$2) -> 0.00095265407 | H2: =SUM(A:A)/COUNT(A:A) -> 0.03558608 | I2: =SQRT(SUM(B:B)/COUNT(A:A)/(COUNT(A:A)-1)) -> 0.0076783095 | J2: 0.95 | K2: =J2*I2 -> 0.007294394 | L2: 1 | M2: =SQRT(K2*K2+(2/3*L2)*(2/3*L2)) -> 0.66670657 | N2: =M2/H2 -> 18.735038
A3: ='Таблица 2'!C4 -> 0.04713408 | B3: =(A3-$H$2)*(A3-$H$2) -> 0.00013335629
A4: ='Таблица 2'!C5 -> 0.037256932 | B4: =(A4-$H$2)*(A4-$H$2) -> 2.7917448e-06
A5: ='Таблица 2'!C6 -> 0.025224089 | B5: =(A5-$H$2)*(A5-$H$2) -> 0.00010737086
A6: ='Таблица 2'!C7 -> 0.020127783 | B6: =(A6-$H$2)*(A6-$H$2) -> 0.00023895896
A7: ='Таблица 2'!C8 -> 0.017322424 | B7: =(A7-$H$2)*(A7-$H$2) -> 0.00033356116

Sheet Погрешности косвенные (a)
A1: Название переменной | B1: a
A2: Формулы частных производных по переменным: | B2: =-4*'Параметры установки'!A2/'Погрешности прямые (t)'!H2/'Погрешности прямые (t)'!H2/'Погрешности прямые (t)'!H2 -> -0.025004428
A3: Среднее значение переменной | B3: ='Погрешности прямые (t)'!H2 -> 4.82
A4: Среднее значение функции | B4: =2*'Параметры установки'!A2/'Погрешности прямые (t)'!H2/'Погрешности прямые (t)'!H2 -> 0.06026067
A5: Абсолютные погрешности переменных | B5: ='Погрешности прямые (t)'!M2 -> 0.67520826
A6: Относительные погрешности переменных | B6: ='Погрешности прямые (t)'!N2 -> 0.1400847
A7: Слагаемые | B7: =B5*B5*B2*B2 -> 0.00028504231
A8: Абсолютная погрешность функции | B8: =SQRT(SUM(7:7)) -> 0.016883196
A9: Относительные погрешности функции | B9: =B8/B4 -> 0.2801694

Sheet Погрешности прямые (e)
A1: Значения x | B1: Квадрат разности (x-xср)2 | H1: Среднее xср | I1: СКО Sxср | J1: Коэфф. Стьюдента tα,n | K1: Доверительный интервал Δxср | L1: Инструментальная погрешность Δиx | M1: Абсолютная погрешность Δx | N1: Относительная погрешность εx
A2: ='Таблица 2'!D3 -> 2.8891815 | B2: =(A2-$H$2)*(A2-$H$2) -> 1.8008584 | H2: =SUM(A:A)/COUNT(A:A) -> 1.5472209 | I2: =SQRT(SUM(B:B)/COUNT(A:A)/(COUNT(A:A)-1)) -> 0.33383954 | J2: 0.95 | K2: =J2*I2 -> 0.31714757 | L2: 1 | M2: =SQRT(K2*K2+(2/3*L2)*(2/3*L2)) -> 0.73825945 | N2: =M2/H2 -> 0.47715195
A3: ='Таблица 2'!D4 -> 2.0493078 | B3: =(A3-$H$2)*(A3-$H$2) -> 0.25209128
A4: ='Таблица 2'!D5 -> 1.6198666 | B4: =(A4-$H$2)*(A4-$H$2) -> 0.0052774004
A5: ='Таблица 2'!D6 -> 1.0966995 | B5: =(A5-$H$2)*(A5-$H$2) -> 0.20296949
A6: ='Таблица 2'!D7 -> 0.87512099 | B6: =(A6-$H$2)*(A6-$H$2) -> 0.45171827
A7: ='Таблица 2'!D8 -> 0.75314885 | B7: =(A7-$H$2)*(A7-$H$2) -> 0.63055039

Sheet Погрешности косвенные (e)
A1: Название переменной | B1: ε
A2: Формулы частных производных по переменным: | B2: =-8*'Параметры установки'!A2/'Параметры установки'!B2/'Погрешности прямые (t)'!H2/'Погрешности прямые (t)'!H2/'Погрешности прямые (t)'!H2 -> -1.087149
A3: Среднее значение переменной | B3: ='Погрешности прямые (t)'!H2 -> 4.82
A4: Среднее значение функции | B4: =4*'Параметры установки'!A2/'Параметры установки'!B2/'Погрешности прямые (t)'!H2/'Погрешности прямые (t)'!H2 -> 2.6200291
A5: Абсолютные погрешности переменных | B5: ='Погрешности прямые (t)'!M2 -> 0.67520826
A6: Относительные погрешности переменных | B6: ='Погрешности прямые (t)'!N2 -> 0.1400847
A7: Слагаемые | B7: =B5*B5*B2*B2 -> 0.53883234
A8: Абсолютная погрешность функции | B8: =SQRT(SUM(7:7)) -> 0.734052
A9: Относительные погрешности функции | B9: =B8/B4 -> 0.2801694

Sheet Погрешности прямые (M)
A1: Значения x | B1: Квадрат разности (x-xср)2 | H1: Среднее xср | I1: СКО Sxср | J1: Коэфф. Стьюдента tα,n | K1: Доверительный интервал Δxср | L1: Инструментальная погрешность Δиx | M1: Абсолютная погрешность Δx | N1: Относительная погрешность εx
A2: ='Таблица 2'!E3 -> 0.059773723 | B2: =(A2-$H$2)*(A2-$H$2) -> 3.5926377e-08 | H2: =SUM(A:A)/COUNT(A:A) -> 0.059963266 | I2: =SQRT(SUM(B:B)/COUNT(A:A)/(COUNT(A:A)-1)) -> 4.7152498e-05 | J2: 0.95 | K2: =J2*I2 -> 4.4794874e-05 | L2: 1 | M2: =SQRT(K2*K2+(2/3*L2)*(2/3*L2)) -> 0.66666667 | N2: =M2/H2 -> 11.117918
A3: ='Таблица 2'!E4 -> 0.05989235 | B3: =(A3-$H$2)*(A3-$H$2) -> 5.0291165e-09
A4: ='Таблица 2'!E5 -> 0.059953005 | B4: =(A4-$H$2)*(A4-$H$2) -> 1.0528195e-10
A5: ='Таблица 2'!E6 -> 0.060026899 | B5: =(A5-$H$2)*(A5-$H$2) -> 4.0491572e-09
A6: ='Таблица 2'!E7 -> 0.060058195 | B6: =(A6-$H$2)*(A6-$H$2) -> 9.011592e-09
A7: ='Таблица 2'!E8 -> 0.060075423 | B7: =(A7-$H$2)*(A7-$H$2) -> 1.2579219e-08

Sheet Погрешности косвенные (M)
A1: Название переменной | B1: M
A2: Формулы частных производных по переменным: | B2: =2*'Таблица 2'!A3*'Параметры установки'!B2*'Параметры установки'!A2/'Погрешности прямые (t)'!H2/'Погрешности прямые (t)'!H2/'Погрешности прямые (t)'!H2 -> 0.00015355219
A3: Среднее значение переменной | B3: ='Погрешности прямые (t)'!H2 -> 4.82
A4: Среднее значение функции | B4: ='Таблица 2'!A3*'Параметры установки'!B2/2*(9.82-2*'Параметры установки'!A2/'Погрешности прямые (t)'!H2/'Погрешности прямые (t)'!H2) -> 0.059934559
A5: Абсолютные погрешности переменных | B5: ='Погрешности прямые (t)'!M2 -> 0.67520826
A6: Относительные погрешности переменных | B6: ='Погрешности прямые (t)'!N2 -> 0.1400847
A7: Слагаемые | B7: =B5*B5*B2*B2 -> 1.0749482e-08
A8: Абсолютная погрешность функции | B8: =SQRT(SUM(7:7)) -> 0.00010367971
A9: Относительные погрешности функции | B9: =B8/B3 -> 2.1510313e-05

Sheet МНК рис.1
A1: x | B1: y | C1: Квадрат разности (x-xср)2 | D1: Квадрат разности (y-yср)2 | E1: Разность x-xср | F1: Разность y-yср | G1: Произведение (x-xср)(y-yср) | H1: d | I1: d2 | J1: Δy | L1: Среднее xср | M1: Среднее yср | N1: b | O1: a | P1: D | Q1: Sb2 | R1: Sa2
A2: ='Таблица 2'!D3 -> 2.8891815 | B2: ='Таблица 2'!E3 -> 0.059773723 | C2: =(A2-$L$2)*(A2-$L$2) -> 8.3188083 | D2: =(B2-$M$2)*(B2-$M$2) -> 0.0052856315 | E2: =A2-$L$2 -> -2.8842344 | F2: =B2-$M$2 -> -0.072702349 | G2: =E2*F2 -> 0.20969062 | H2: =B2-($O$2+$N$2*A2) -> 0.0033611659 | I2: =H2*H2 -> 1.1297436e-05 | J2: =SQRT(4*$R$2+4*$Q$2*A2*A2) -> 0.023518275 | L2: =SUM(A:A)/COUNT(A:A) -> 5.773416 | M2: =SUM(B:B)/COUNT(B:B) -> 0.13247607 | N2: =SUM(G:G)/SUM(C:C) -> 0.026372168 | O2: =M2-N2*L2 -> -0.019781423 | P2: =SUM(C:C) -> 16.668287 | Q2: =1/P2*SUM(I:I)/(COUNT(I:I)-2) -> 3.0160752e-06 | R2: =(1/COUNT(I:I)+L2*L2/P2)*SUM(I:I)/(COUNT(I:I)-2) -> 0.00011310102
A3: ='Таблица 2'!D9 -> 4.9689441 | B3: ='Таблица 2'!E9 -> 0.10848969 | C3: =(A3-$L$2)*(A3-$L$2) -> 0.64717498 | D3: =(B3-$M$2)*(B3-$M$2) -> 0.00057534673 | E3: =A3-$L$2 -> -0.80447186 | F3: =B3-$M$2 -> -0.023986386 | G3: =E3*F3 -> 0.019296373 | H3: =B3-($O$2+$N$2*A3) -> -0.0027707194 | I3: =H3*H3 -> 7.676886e-06 | J3: =SQRT(4*$R$2+4*$Q$2*A3*A3) -> 0.027391177 | N3: I | O3: Mтр | Q3: Sb | R3: Sa
A4: ='Таблица 2'!D15 -> 6.9473116 | B4: ='Таблица 2'!E15 -> 0.15675948 | C4: =(A4-$L$2)*(A4-$L$2) -> 1.3780309 | D4: =(B4-$M$2)*(B4-$M$2) -> 0.00058968413 | E4: =A4-$L$2 -> 1.1738956 | F4: =B4-$M$2 -> 0.024283413 | G4: =E4*F4 -> 0.028506192 | H4: =B4-($O$2+$N$2*A4) -> -0.0066747599 | I4: =H4*H4 -> 4.455242e-05 | J4: =SQRT(4*$R$2+4*$Q$2*A4*A4) -> 0.032166585 | Q4: =SQRT(Q2) -> 0.0017366851 | R4: =SQRT(R2) -> 0.010634896
A5: ='Таблица 2'!D21 -> 8.2882266 | B5: ='Таблица 2'!E21 -> 0.20488139 | C5: =(A5-$L$2)*(A5-$L$2) -> 6.3242727 | D5: =(B5-$M$2)*(B5-$M$2) -> 0.0052425307 | E5: =A5-$L$2 -> 2.5148107 | F5: =B5-$M$2 -> 0.072405323 | G5: =E5*F5 -> 0.18208568 | H5: =B5-($O$2+$N$2*A5) -> 0.0060843134 | I5: =H5*H5 -> 3.701887e-05 | J5: =SQRT(4*$R$2+4*$Q$2*A5*A5) -> 0.035793262 | Q5: 2Sb = Δb | R5: 2Sa = Δa
Q6: =Q4*2 -> 0.0034733702 | R6: =R4*2 -> 0.021269793

Sheet МНК рис.2
A1: x | B1: y | C1: Квадрат разности (x-xср)2 | D1: Квадрат разности (y-yср)2 | E1: Разность x-xср | F1: Разность y-yср | G1: Произведение (x-xср)(y-yср) | H1: d | I1: d2 | J1: Δy | L1: Среднее xср | M1: Среднее yср | N1: b | O1: a | P1: D | Q1: Sb2 | R1: Sa2
A2: ='Таблица 2'!D4 -> 2.0493078 | B2: ='Таблица 2'!E4 -> 0.05989235 | C2: =(A2-$L$2)*(A2-$L$2) -> 4.9879745 | D2: =(B2-$M$2)*(B2-$M$2) -> 0.0053457507 | E2: =A2-$L$2 -> -2.2333774 | F2: =B2-$M$2 -> -0.073114641 | G2: =E2*F2 -> 0.16329259 | H2: =B2-($O$2+$N$2*A2) -> 0.003260315 | I2: =H2*H2 -> 1.0629654e-05 | J2: =SQRT(4*$R$2+4*$Q$2*A2*A2) -> 0.027733776 | L2: =SUM(A:A)/COUNT(A:A) -> 4.2826852 | M2: =SUM(B:B)/COUNT(B:B) -> 0.13300699 | N2: =SUM(G:G)/SUM(C:C) -> 0.034197067 | O2: =M2-N2*L2 -> -0.013448282 | P2: =SUM(C:C) -> 9.9886853 | Q2: =1/P2*SUM(I:I)/(COUNT(I:I)-2) -> 7.6798806e-06 | R2: =(1/COUNT(I:I)+L2*L2/P2)*SUM(I:I)/(COUNT(I:I)-2) -> 0.00016003768
A3: ='Таблица 2'!D10 -> 3.8620615 | B3: ='Таблица 2'!E10 -> 0.10877484 | C3: =(A3-$L$2)*(A3-$L$2) -> 0.17692428 | D3: =(B3-$M$2)*(B3-$M$2) -> 0.00058719692 | E3: =A3-$L$2 -> -0.42062368 | F3: =B3-$M$2 -> -0.024232146 | G3: =E3*F3 -> 0.010192615 | H3: =B3-($O$2+$N$2*A3) -> -0.0098480501 | I3: =H3*H3 -> 9.698409e-05 | J3: =SQRT(4*$R$2+4*$Q$2*A3*A3) -> 0.033141339 | N3: I | O3: Mтр | Q3: Sb | R3: Sa
A4: ='Таблица 2'!D16 -> 4.8028631 | B4: ='Таблица 2'!E16 -> 0.15756151 | C4: =(A4-$L$2)*(A4-$L$2) -> 0.27058501 | D4: =(B4-$M$2)*(B4-$M$2) -> 0.00060292467 | E4: =A4-$L$2 -> 0.52017786 | F4: =B4-$M$2 -> 0.024554524 | G4: =E4*F4 -> 0.01277272 | H4: =B4-($O$2+$N$2*A4) -> 0.0067659671 | I4: =H4*H4 -> 4.5778311e-05 | J4: =SQRT(4*$R$2+4*$Q$2*A4*A4) -> 0.036725647 | Q4: =SQRT(Q2) -> 0.0027712598 | R4: =SQRT(R2) -> 0.0126506
A5: ='Таблица 2'!D22 -> 6.4165084 | B5: ='Таблица 2'!E22 -> 0.20579925 | C5: =(A5-$L$2)*(A5-$L$2) -> 4.5532015 | D5: =(B5-$M$2)*(B5-$M$2) -> 0.0052987135 | E5: =A5-$L$2 -> 2.1338232 | F5: =B5-$M$2 -> 0.072792263 | G5: =E5*F5 -> 0.15532582 | H5: =B5-($O$2+$N$2*A5) -> -0.00017823202 | I5: =H5*H5 -> 3.1766652e-08 | J5: =SQRT(4*$R$2+4*$Q$2*A5*A5) -> 0.043645412 | Q5: 2Sb = Δb | R5: 2Sa = Δa
Q6: =Q4*2 -> 0.0055425195 | R6: =R4*2 -> 0.0253012

Sheet МНК рис.3
A1: x | B1: y | C1: Квадрат разности (x-xср)2 | D1: Квадрат разности (y-yср)2 | E1: Разность x-xср | F1: Разность y-yср | G1: Произведение (x-xср)(y-yср) | H1: d | I1: d2 | J1: Δy | L1: Среднее xср | M1: Среднее yср | N1: b | O1: a | P1: D | Q1: Sb2 | R1: Sa2
A2: ='Таблица 2'!D5 -> 1.6198666 | B2: ='Таблица 2'!E5 -> 0.059953005 | C2: =(A2-$L$2)*(A2-$L$2) -> 3.1398203 | D2: =(B2-$M$2)*(B2-$M$2) -> 0.0053830646 | E2: =A2-$L$2 -> -1.7719538 | F2: =B2-$M$2 -> -0.073369371 | G2: =E2*F2 -> 0.13000714 | H2: =B2-($O$2+$N$2*A2) -> -9.1302078e-05 | I2: =H2*H2 -> 8.3360694e-09 | J2: =SQRT(4*$R$2+4*$Q$2*A2*A2) -> 0.022014864 | L2: =SUM(A:A)/COUNT(A:A) -> 3.3918204 | M2: =SUM(B:B)/COUNT(B:B) -> 0.13332238 | N2: =SUM(G:G)/SUM(C:C) -> 0.04135439 | O2: =M2-N2*L2 -> -0.0069442879 | P2: =SUM(C:C) -> 6.906671 | Q2: =1/P2*SUM(I:I)/(COUNT(I:I)-2) -> 7.6419389e-06 | R2: =(1/COUNT(I:I)+L2*L2/P2)*SUM(I:I)/(COUNT(I:I)-2) -> 0.00010111136
A3: ='Таблица 2'!D11 -> 2.9273221 | B3: ='Таблица 2'!E11 -> 0.10901565 | C3: =(A3-$L$2)*(A3-$L$2) -> 0.21575866 | D3: =(B3-$M$2)*(B3-$M$2) -> 0.00059081671 | E3: =A3-$L$2 -> -0.46449828 | F3: =B3-$M$2 -> -0.024306722 | G3: =E3*F3 -> 0.01129043 | H3: =B3-($O$2+$N$2*A3) -> -0.0050976783 | I3: =H3*H3 -> 2.5986324e-05 | J3: =SQRT(4*$R$2+4*$Q$2*A3*A3) -> 0.025814475 | N3: I | O3: Mтр | Q3: Sb | R3: Sa
A4: ='Таблица 2'!D17 -> 3.7853972 | B4: ='Таблица 2'!E17 -> 0.15794205 | C4: =(A4-$L$2)*(A4-$L$2) -> 0.15490268 | D4: =(B4-$M$2)*(B4-$M$2) -> 0.00060612835 | E4: =A4-$L$2 -> 0.39357678 | F4: =B4-$M$2 -> 0.024619674 | G4: =E4*F4 -> 0.009689732 | H4: =B4-($O$2+$N$2*A4) -> 0.0083435465 | I4: =H4*H4 -> 6.9614768e-05 | J4: =SQRT(4*$R$2+4*$Q$2*A4*A4) -> 0.029025125 | Q4: =SQRT(Q2) -> 0.0027644057 | R4: =SQRT(R2) -> 0.010055414
A5: ='Таблица 2'!D23 -> 5.2346957 | B5: ='Таблица 2'!E23 -> 0.20637879 | C5: =(A5-$L$2)*(A5-$L$2) -> 3.3961894 | D5: =(B5-$M$2)*(B5-$M$2) -> 0.0053372402 | E5: =A5-$L$2 -> 1.8428753 | F5: =B5-$M$2 -> 0.073056418 | G5: =E5*F5 -> 0.13463387 | H5: =B5-($O$2+$N$2*A5) -> -0.0031545661 | I5: =H5*H5 -> 9.9512875e-06 | J5: =SQRT(4*$R$2+4*$Q$2*A5*A5) -> 0.035242932 | Q5: 2Sb = Δb | R5: 2Sa = Δa
Q6: =Q4*2 -> 0.0055288114 | R6: =R4*2 -> 0.020110829

Sheet МНК рис.4
A1: x | B1: y | C1: Квадрат разности (x-xср)2 | D1: Квадрат разности (y-yср)2 | E1: Разность x-xср | F1: Разность y-yср | G1: Произведение (x-xср)(y-yср) | H1: d | I1: d2 | J1: Δy | L1: Среднее xср | M1: Среднее yср | N1: b | O1: a | P1: D | Q1: Sb2 | R1: Sa2
A2: ='Таблица 2'!D6 -> 1.0966995 | B2: ='Таблица 2'!E6 -> 0.060026899 | C2: =(A2-$L$2)*(A2-$L$2) -> 2.3060517 | D2: =(B2-$M$2)*(B2-$M$2) -> 0.0054113216 | E2: =A2-$L$2 -> -1.518569 | F2: =B2-$M$2 -> -0.073561686 | G2: =E2*F2 -> 0.11170849 | H2: =B2-($O$2+$N$2*A2) -> -0.0012617106 | I2: =H2*H2 -> 1.5919136e-06 | J2: =SQRT(4*$R$2+4*$Q$2*A2*A2) -> 0.0095359851 | L2: =SUM(A:A)/COUNT(A:A) -> 2.6152685 | M2: =SUM(B:B)/COUNT(B:B) -> 0.13358858 | N2: =SUM(G:G)/SUM(C:C) -> 0.047610597 | O2: =M2-N2*L2 -> 0.0090740907 | P2: =SUM(C:C) -> 5.2761244 | Q2: =1/P2*SUM(I:I)/(COUNT(I:I)-2) -> 2.4284539e-06 | R2: =(1/COUNT(I:I)+L2*L2/P2)*SUM(I:I)/(COUNT(I:I)-2) -> 1.981293e-05
A3: ='Таблица 2'!D12 -> 2.0343494 | B3: ='Таблица 2'!E12 -> 0.1092457 | C3: =(A3-$L$2)*(A3-$L$2) -> 0.33746698 | D3: =(B3-$M$2)*(B3-$M$2) -> 0.00059257579 | E3: =A3-$L$2 -> -0.58091908 | F3: =B3-$M$2 -> -0.02434288 | G3: =E3*F3 -> 0.014141243 | H3: =B3-($O$2+$N$2*A3) -> 0.0033150246 | I3: =H3*H3 -> 1.0989388e-05 | J3: =SQRT(4*$R$2+4*$Q$2*A3*A3) -> 0.01092946 | N3: I | O3: Mтр | Q3: Sb | R3: Sa
A4: ='Таблица 2'!D18 -> 3.2020435 | B4: ='Таблица 2'!E18 -> 0.15816023 | C4: =(A4-$L$2)*(A4-$L$2) -> 0.34430486 | D4: =(B4-$M$2)*(B4-$M$2) -> 0.00060376558 | E4: =A4-$L$2 -> 0.58677496 | F4: =B4-$M$2 -> 0.024571642 | G4: =E4*F4 -> 0.014418024 | H4: =B4-($O$2+$N$2*A4) -> -0.0033650644 | I4: =H4*H4 -> 1.1323659e-05 | J4: =SQRT(4*$R$2+4*$Q$2*A4*A4) -> 0.013373417 | Q4: =SQRT(Q2) -> 0.0015583497 | R4: =SQRT(R2) -> 0.0044511718
A5: ='Таблица 2'!D24 -> 4.1279816 | B5: ='Таблица 2'!E24 -> 0.20692151 | C5: =(A5-$L$2)*(A5-$L$2) -> 2.2883009 | D5: =(B5-$M$2)*(B5-$M$2) -> 0.0053777177 | E5: =A5-$L$2 -> 1.5127131 | F5: =B5-$M$2 -> 0.073332924 | G5: =E5*F5 -> 0.11093167 | H5: =B5-($O$2+$N$2*A5) -> 0.0013117504 | I5: =H5*H5 -> 1.7206892e-06 | J5: =SQRT(4*$R$2+4*$Q$2*A5*A5) -> 0.015645363 | Q5: 2Sb = Δb | R5: 2Sa = Δa
Q6: =Q4*2 -> 0.0031166995 | R6: =R4*2 -> 0.0089023436

Sheet МНК рис.5
A1: x | B1: y | C1: Квадрат разности (x-xср)2 | D1: Квадрат разности (y-yср)2 | E1: Разность x-xср | F1: Разность y-yср | G1: Произведение (x-xср)(y-yср) | H1: d | I1: d2 | J1: Δy | L1: Среднее xср | M1: Среднее yср | N1: b | O1: a | P1: D | Q1: Sb2 | R1: Sa2
A2: ='Таблица 2'!D7 -> 0.87512099 | B2: ='Таблица 2'!E7 -> 0.060058195 | C2: =(A2-$L$2)*(A2-$L$2) -> 1.2887473 | D2: =(B2-$M$2)*(B2-$M$2) -> 0.0054421489 | E2: =A2-$L$2 -> -1.1352301 | F2: =B2-$M$2 -> -0.073770922 | G2: =E2*F2 -> 0.083746969 | H2: =B2-($O$2+$N$2*A2) -> -0.00032639248 | I2: =H2*H2 -> 1.0653205e-07 | J2: =SQRT(4*$R$2+4*$Q$2*A2*A2) -> 0.070220746 | L2: =SUM(A:A)/COUNT(A:A) -> 2.0103511 | M2: =SUM(B:B)/COUNT(B:B) -> 0.13382912 | N2: =SUM(G:G)/SUM(C:C) -> 0.064695723 | O2: =M2-N2*L2 -> 0.0037680032 | P2: =SUM(C:C) -> 2.6051979 | Q2: =1/P2*SUM(I:I)/(COUNT(I:I)-2) -> 0.00022583218 | R2: =(1/COUNT(I:I)+L2*L2/P2)*SUM(I:I)/(COUNT(I:I)-2) -> 0.0010597877
A3: ='Таблица 2'!D13 -> 1.6198666 | B3: ='Таблица 2'!E13 -> 0.10935249 | C3: =(A3-$L$2)*(A3-$L$2) -> 0.15247811 | D3: =(B3-$M$2)*(B3-$M$2) -> 0.00059910552 | E3: =A3-$L$2 -> -0.39048445 | F3: =B3-$M$2 -> -0.024476632 | G3: =E3*F3 -> 0.0095577443 | H3: =B3-($O$2+$N$2*A3) -> 0.00078604168 | I3: =H3*H3 -> 6.1786153e-07 | J3: =SQRT(4*$R$2+4*$Q$2*A3*A3) -> 0.081298563 | N3: I | O3: Mтр | Q3: Sb | R3: Sa
A4: ='Таблица 2'!D19 -> 2.767289 | B4: ='Таблица 2'!E19 -> 0.15832283 | C4: =(A4-$L$2)*(A4-$L$2) -> 0.57295503 | D4: =(B4-$M$2)*(B4-$M$2) -> 0.00059994175 | E4: =A4-$L$2 -> 0.75693793 | F4: =B4-$M$2 -> 0.024493708 | G4: =E4*F4 -> 0.018540217 | H4: =B4-($O$2+$N$2*A4) -> -0.024476938 | I4: =H4*H4 -> 0.0005991205 | J4: =SQRT(4*$R$2+4*$Q$2*A4*A4) -> 0.10562548 | Q4: =SQRT(Q2) -> 0.015027714 | R4: =SQRT(R2) -> 0.032554381
A5: ='Таблица 2'!D25 -> 2.7791276 | B5: ='Таблица 2'!E25 -> 0.20758296 | C5: =(A5-$L$2)*(A5-$L$2) -> 0.59101744 | D5: =(B5-$M$2)*(B5-$M$2) -> 0.0054396298 | E5: =A5-$L$2 -> 0.76877659 | F5: =B5-$M$2 -> 0.073753846 | G5: =E5*F5 -> 0.05670023 | H5: =B5-($O$2+$N$2*A5) -> 0.024017289 | I5: =H5*H5 -> 0.00057683017 | J5: =SQRT(4*$R$2+4*$Q$2*A5*A5) -> 0.10590588 | Q5: 2Sb = Δb | R5: 2Sa = Δa
Q6: =Q4*2 -> 0.030055428 | R6: =R4*2 -> 0.065108762

Sheet МНК рис.6
A1: x | B1: y | C1: Квадрат разности (x-xср)2 | D1: Квадрат разности (y-yср)2 | E1: Разность x-xср | F1: Разность y-yср | G1: Произведение (x-xср)(y-yср) | H1: d | I1: d2 | J1: Δy | L1: Среднее xср | M1: Среднее yср | N1: b | O1: a | P1: D | Q1: Sb2 | R1: Sa2
A2: ='Таблица 2'!D8 -> 0.75314885 | B2: ='Таблица 2'!E8 -> 0.060075423 | C2: =(A2-$L$2)*(A2-$L$2) -> 0.70272036 | D2: =(B2-$M$2)*(B2-$M$2) -> 0.0054624948 | E2: =A2-$L$2 -> -0.83828418 | F2: =B2-$M$2 -> -0.073908692 | G2: =E2*F2 -> 0.061956487 | H2: =B2-($O$2+$N$2*A2) -> 0.0036210319 | I2: =H2*H2 -> 1.3111872e-05 | J2: =SQRT(4*$R$2+4*$Q$2*A2*A2) -> 0.016519714 | L2: =SUM(A:A)/COUNT(A:A) -> 1.591433 | M2: =SUM(B:B)/COUNT(B:B) -> 0.13398412 | N2: =SUM(G:G)/SUM(C:C) -> 0.092486208 | O2: =M2-N2*L2 -> -0.01320149 | P2: =SUM(C:C) -> 1.410704 | Q2: =1/P2*SUM(I:I)/(COUNT(I:I)-2) -> 1.9760722e-05 | R2: =(1/COUNT(I:I)+L2*L2/P2)*SUM(I:I)/(COUNT(I:I)-2) -> 5.7016304e-05
A3: ='Таблица 2'!D14 -> 1.3764388 | B3: ='Таблица 2'!E14 -> 0.1094152 | C3: =(A3-$L$2)*(A3-$L$2) -> 0.046222513 | D3: =(B3-$M$2)*(B3-$M$2) -> 0.00060363172 | E3: =A3-$L$2 -> -0.21499422 | F3: =B3-$M$2 -> -0.024568918 | G3: =E3*F3 -> 0.0052821752 | H3: =B3-($O$2+$N$2*A3) -> -0.0046849181 | I3: =H3*H3 -> 2.1948457e-05 | J3: =SQRT(4*$R$2+4*$Q$2*A3*A3) -> 0.019437556 | N3: I | O3: Mтр | Q3: Sb | R3: Sa
A4: ='Таблица 2'!D20 -> 1.8867029 | B4: ='Таблица 2'!E20 -> 0.15865217 | C4: =(A4-$L$2)*(A4-$L$2) -> 0.087184328 | D4: =(B4-$M$2)*(B4-$M$2) -> 0.00060851279 | E4: =A4-$L$2 -> 0.29526992 | F4: =B4-$M$2 -> 0.024668052 | G4: =E4*F4 -> 0.0072837338 | H4: =B4-($O$2+$N$2*A4) -> -0.0026403435 | I4: =H4*H4 -> 6.9714136e-06 | J4: =SQRT(4*$R$2+4*$Q$2*A4*A4) -> 0.022570558 | Q4: =SQRT(Q2) -> 0.0044453033 | R4: =SQRT(R2) -> 0.0075509141
A5: ='Таблица 2'!D26 -> 2.3494415 | B5: ='Таблица 2'!E26 -> 0.20779367 | C5: =(A5-$L$2)*(A5-$L$2) -> 0.57457684 | D5: =(B5-$M$2)*(B5-$M$2) -> 0.0054478509 | E5: =A5-$L$2 -> 0.75800847 | F5: =B5-$M$2 -> 0.073809558 | G5: =E5*F5 -> 0.05594827 | H5: =B5-($O$2+$N$2*A5) -> 0.0037042297 | I5: =H5*H5 -> 1.3721317e-05 | J5: =SQRT(4*$R$2+4*$Q$2*A5*A5) -> 0.025775416 | Q5: 2Sb = Δb | R5: 2Sa = Δa
Q6: =Q4*2 -> 0.0088906067 | R6: =R4*2 -> 0.015101828

Sheet МНК I
A1: x | B1: y | C1: Квадрат разности (x-xср)2 | D1: Квадрат разности (y-yср)2 | E1: Разность x-xср | F1: Разность y-yср | G1: Произведение (x-xср)(y-yср) | H1: d | I1: d2 | J1: Δy | L1: Среднее xср | M1: Среднее yср | N1: b | O1: a | P1: D | Q1: Sb2 | R1: Sa2
A2: ='Таблица 3'!B3 -> 0.005929 | B2: ='Таблица 3'!B4 -> 0.026372168 | C2: =(A2-$L$2)*(A2-$L$2) -> 0.00023575043 | D2: =(B2-$M$2)*(B2-$M$2) -> 0.00061242345 | E2: =A2-$L$2 -> -0.015354167 | F2: =B2-$M$2 -> -0.024747191 | G2: =E2*F2 -> 0.00037997249 | H2: =B2-($O$2+$N$2*A2) -> 0.0027692249 | I2: =H2*H2 -> 7.6686068e-06 | J2: =SQRT(4*$R$2+4*$Q$2*A2*A2) -> 0.0093919738 | L2: =SUM(A:A)/COUNT(A:A) -> 0.021283167 | M2: =SUM(B:B)/COUNT(B:B) -> 0.051119359 | N2: =SUM(G:G)/SUM(C:C) -> 1.7921139 | O2: =M2-N2*L2 -> 0.012977499 | P2: =SUM(C:C) -> 0.00086596927 | Q2: =1/P2*SUM(I:I)/(COUNT(I:I)-2) -> 0.034867797 | R2: =(1/COUNT(I:I)+L2*L2/P2)*SUM(I:I)/(COUNT(I:I)-2) -> 2.0826584e-05
A3: ='Таблица 3'!C3 -> 0.010404 | B3: ='Таблица 3'!C4 -> 0.034197067 | C3: =(A3-$L$2)*(A3-$L$2) -> 0.00011835627 | D3: =(B3-$M$2)*(B3-$M$2) -> 0.00028636396 | E3: =A3-$L$2 -> -0.010879167 | F3: =B3-$M$2 -> -0.016922292 | G3: =E3*F3 -> 0.00018410043 | H3: =B3-($O$2+$N$2*A3) -> 0.0025744143 | I3: =H3*H3 -> 6.627609e-06 | J3: =SQRT(4*$R$2+4*$Q$2*A3*A3) -> 0.009919836 | N3: 4mут | O3: I0 | Q3: Sb | R3: Sa
A4: ='Таблица 3'!D3 -> 0.016129 | B4: ='Таблица 3'!D4 -> 0.04135439 | C4: =(A4-$L$2)*(A4-$L$2) -> 2.6565434e-05 | D4: =(B4-$M$2)*(B4-$M$2) -> 9.5354612e-05 | E4: =A4-$L$2 -> -0.0051541667 | F4: =B4-$M$2 -> -0.0097649686 | G4: =E4*F4 -> 5.0330276e-05 | H4: =B4-($O$2+$N$2*A4) -> -0.00052811478 | I4: =H4*H4 -> 2.7890522e-07 | J4: =SQRT(4*$R$2+4*$Q$2*A4*A4) -> 0.010935676 | Q4: =SQRT(Q2) -> 0.18672921 | R4: =SQRT(R2) -> 0.0045636152
A5: ='Таблица 3'!E3 -> 0.023104 | B5: ='Таблица 3'!E4 -> 0.047610597 | C5: =(A5-$L$2)*(A5-$L$2) -> 3.315434e-06 | D5: =(B5-$M$2)*(B5-$M$2) -> 1.2311409e-05 | E5: =A5-$L$2 -> 0.0018208333 | F5: =B5-$M$2 -> -0.0035087618 | G5: =E5*F5 -> -6.3888704e-06 | H5: =B5-($O$2+$N$2*A5) -> -0.0067719025 | I5: =H5*H5 -> 4.5858664e-05 | J5: =SQRT(4*$R$2+4*$Q$2*A5*A5) -> 0.012560069 | Q5: 2Sb = Δb | R5: 2Sa = Δa
A6: ='Таблица 3'!F3 -> 0.031329 | B6: ='Таблица 3'!F4 -> 0.064695723 | C6: =(A6-$L$2)*(A6-$L$2) -> 0.00010091877 | D6: =(B6-$M$2)*(B6-$M$2) -> 0.00018431766 | E6: =A6-$L$2 -> 0.010045833 | F6: =B6-$M$2 -> 0.013576364 | G6: =E6*F6 -> 0.00013638589 | H6: =B6-($O$2+$N$2*A6) -> -0.0044269137 | I6: =H6*H6 -> 1.9597565e-05 | J6: =SQRT(4*$R$2+4*$Q$2*A6*A6) -> 0.014839076 | Q6: =Q4*2 -> 0.37345842 | R6: =R4*2 -> 0.0091272305
A7: ='Таблица 3'!G3 -> 0.040804 | B7: ='Таблица 3'!G4 -> 0.092486208 | C7: =(A7-$L$2)*(A7-$L$2) -> 0.00038106293 | D7: =(B7-$M$2)*(B7-$M$2) -> 0.0017112162 | E7: =A7-$L$2 -> 0.019520833 | F7: =B7-$M$2 -> 0.041366849 | G7: =E7*F7 -> 0.00080751536 | H7: =B7-($O$2+$N$2*A7) -> 0.0063832918 | I7: =H7*H7 -> 4.0746414e-05 | J7: =SQRT(4*$R$2+4*$Q$2*A7*A7) -> 0.017762916
